Workbook

Sheet Leia-me
A1: DairyUp - Modelo financeiro (60 meses)
A3: RESUMO EXECUTIVO (cenário base, valores gerados pelo modelo)
A4: Sistema de gestão da qualidade do leite e do rebanho (DairyUp), assinatura por vaca/mês. Ano 5: 860 fazendas, 146.191 vacas, ARR de R$ 19.456.171, EBITDA de R$ 4.993.036.
A5: Aporte solicitado: R$ 4.700.000 (3 parcelas por marcos). Necessidade máxima de caixa: R$ 4.044.057. Break-even operacional no mês 32; payback no mês 54.
A6: VPL com valor residual: R$ 7.476.441; sem valor residual: R$ -226.236. TIR sem valor residual: 22%.
A7: Decisão: aprovar o investimento e o lançamento comercial no mês 4. Detalhes: aba Anual, Retornos e Cenários e sensibilidade.
A9: Planilha-mestre do plano de negócios. Todos os números do deck e do documento vêm daqui.
A11: COMO USAR
A12: 1) Edite apenas as células em AZUL com fundo AMARELO na aba "Premissas". Todas as demais abas são fórmulas.
A13: 2) Para trocar de cenário, altere "Cenário ativo" (1 = Conservador, 2 = Base, 3 = Otimista) na aba Premissas.
A14: 3) A aba "Cenários e sensibilidade" guarda resultados já calculados (valores) dos 3 cenários e das grades de sensibilidade; para atualizá-los depois de mudar premissas, altere o cenário e leia as abas Anual/Retornos.
A16: ABAS
... A26: Simplificações: sem depreciação, juros e imposto sobre lucro (carga tributária incide sobre a receita); desenvolvimento tratado como despesa (sem capitalização); caixa sem rendimento financeiro.

Sheet Premissas
A1: Premissas (edite as células azuis/amarelas)
A3: Premissa | B3: Valor | C3: Unidade | D3: Fonte / observação
A4: Geral
A5: Mês de lançamento comercial (1º cliente pagante) | B5: 4 | C5: mês | D5: Marco: MVP endurecido + 3 pilotos concluídos. Premissa de projeto.
A6: Reajuste anual de preços e salários (IPCA) | B6: 0.05 | C6: % a.a. | D6: Premissa; aplicado a partir do ano 2.
A7: Prazo médio de recebimento | B7: 10 | C7: dias | D7: Cobrança mensal antecipada via boleto/PIX; premissa.
A8: Prazo médio de pagamento (fornecedores e encargos) | B8: 20 | C8: dias | D8: Premissa.
A9: Taxa de desconto (TMA) para VPL | B9: 0.25 | C9: % a.a. | D9: Premissa de custo de capital de risco para startup de software (Selic + prêmio).
A10: Múltiplo de valor residual (EV / receita líquida do ano 5) | B10: 1.5 | C10: x | D10: Premissa conservadora para SaaS vertical; o VPL é mostrado também SEM valor residual.
A11: Preços (por plano)
A12: Mix de fazendas - Essencial | B12: 0.5 | C12: % | D12: Premissa. Mix soma 100%.
A13: Mix de fazendas - Profissional | B13: 0.38 | C13: % | D13: Premissa.
A14: Mix de fazendas - Premium | B14: =1-mix_ess-mix_pro -> 0.12 | C14: % | D14: Calculado: 100% - demais.
A15: Vacas em lactação por fazenda - Essencial | B15: 80 | C15: vacas | D15: Premissa: pequeno porte (até ~120 vacas).
A16: Vacas em lactação por fazenda - Profissional | B16: 200 | C16: vacas | D16: Premissa: médio porte (120 a 400). Piloto Mariana: ~300-400 vacas.
A17: Vacas em lactação por fazenda - Premium | B17: 450 | C17: vacas | D17: Premissa: grande porte (acima de 400).
A18: Preço Essencial por vaca/mês | B18: 4.5 | C18: R$/vaca/mês | D18: Premissa; a validar com 10 entrevistas de preço (ver plano).
A19: Preço Profissional por vaca/mês | B19: 7 | C19: R$/vaca/mês | D19: Premissa.
A20: Preço Premium por vaca/mês | B20: 10 | C20: R$/vaca/mês | D20: Premissa.
A21: Mensalidade mínima - Essencial | B21: 320 | C21: R$/mês | D21: Premissa.
A22: Mensalidade mínima - Profissional | B22: 950 | C22: R$/mês | D22: Premissa.
A23: Mensalidade mínima - Premium | B23: 2000 | C23: R$/mês | D23: Premissa.
A24: Implantação (taxa única) - Essencial | B24: 1200 | C24: R$ | D24: Premissa: importação de histórico + treinamento.
A25: Implantação (taxa única) - Profissional | B25: 2800 | C25: R$ | D25: Premissa.
A26: Implantação (taxa única) - Premium | B26: 6000 | C26: R$ | D26: Premissa.
... A29: Licença de consultor/veterinário por mês | B29: 600 | C29: R$/mês | D29: Premissa: painel multi-fazendas.
A30: Crescimento e retenção
A31: Churn mensal de fazendas (cenário base) | B31: 0.012 | C31: % a.m. | D31: Premissa (~13,5% ao ano); meta de retenção do plano de sucesso do cliente.
A32: Custos variáveis e infraestrutura
A33: Infraestrutura por fazenda (banco isolado, app, backup) | B33: 75 | C33: R$/fazenda/mês | D33: Premissa: um banco por fazenda (isolamento) na AWS.
A34: Mensageria (WhatsApp/e-mail/SMS) por fazenda | B34: 30 | C34: R$/fazenda/mês | D34: Premissa.
A35: Infraestrutura fixa (monitoramento, CI/CD, segredos, backup central) | B35: 4000 | C35: R$/mês | D35: Premissa.
A36: Suporte e Sucesso do Cliente (dimensionamento)
A37: Fazendas por atendente N1 | B37: 150 | C37: fazendas | D37: Premissa de capacidade (chat/WhatsApp, 1ª resposta).
A38: Fazendas por gerente de sucesso (CS) | B38: 100 | C38: fazendas | D38: Premissa.
A39: Vacas atendidas por analista zootécnico/vet N2 | B39: 30000 | C39: vacas | D39: Premissa: interpretação de indicadores e protocolos.
A40: Novas fazendas/mês por especialista de implantação | B40: 8 | C40: fazendas/mês | D40: Premissa: ~25 h de implantação por fazenda.
A41: Base de fazendas a partir da qual existe atendente N1 dedicado | B41: 30 | C41: fazendas | D41: Antes disso o N1 é feito por CS e N2 (equipe enxuta no início).
A42: Custo mensal N1 (salário + encargos) | B42: 4500 | C42: R$/mês | D42: Premissa; valores do ano 1, reajustados.
A43: Custo mensal CS | B43: 8000 | C43: R$/mês | D43: Premissa.
...

Sheet Anual
A1: DRE, fluxo de caixa, balanço e indicadores (anual)
A3: R$ (exceto onde indicado) | B3: 1 | C3: 2 | D3: 3 | E3: 4 | F3: 5
A4: DEMONSTRAÇÃO DO RESULTADO (DRE)
A5: Assinaturas (por vaca/mês) | B5: =SUMIFS(Mensal!$C$17:$BJ$17,Mensal!$C$6:$BJ$6,B$3) -> 147610.31 | C5: =SUMIFS(Mensal!$C$17:$BJ$17,Mensal!$C$6:$BJ$6,C$3) -> 1467278 | D5: =SUMIFS(Mensal!$C$17:$BJ$17,Mensal!$C$6:$BJ$6,D$3) -> 4329265.2 | E5: =SUMIFS(Mensal!$C$17:$BJ$17,Mensal!$C$6:$BJ$6,E$3) -> 8442476.3 | F5: =SUMIFS(Mensal!$C$17:$BJ$17,Mensal!$C$6:$BJ$6,F$3) -> 13425655
A6: Implantação | B6: =SUMIFS(Mensal!$C$18:$BJ$18,Mensal!$C$6:$BJ$6,B$3) -> 64368 | C6: =SUMIFS(Mensal!$C$18:$BJ$18,Mensal!$C$6:$BJ$6,C$3) -> 360460.8 | D6: =SUMIFS(Mensal!$C$18:$BJ$18,Mensal!$C$6:$BJ$6,D$3) -> 630806.4 | E6: =SUMIFS(Mensal!$C$18:$BJ$18,Mensal!$C$6:$BJ$6,E$3) -> 861050.74 | F6: =SUMIFS(Mensal!$C$18:$BJ$18,Mensal!$C$6:$BJ$6,F$3) -> 1043196.1
A7: Módulos premium | B7: =SUMIFS(Mensal!$C$19:$BJ$19,Mensal!$C$6:$BJ$6,B$3) -> 0 | C7: =SUMIFS(Mensal!$C$19:$BJ$19,Mensal!$C$6:$BJ$6,C$3) -> 41018.154 | D7: =SUMIFS(Mensal!$C$19:$BJ$19,Mensal!$C$6:$BJ$6,D$3) -> 217846.41 | E7: =SUMIFS(Mensal!$C$19:$BJ$19,Mensal!$C$6:$BJ$6,E$3) -> 590029.3 | F7: =SUMIFS(Mensal!$C$19:$BJ$19,Mensal!$C$6:$BJ$6,F$3) -> 1125953.5
A8: Benchmark premium | B8: =SUMIFS(Mensal!$C$20:$BJ$20,Mensal!$C$6:$BJ$6,B$3) -> 0 | C8: =SUMIFS(Mensal!$C$20:$BJ$20,Mensal!$C$6:$BJ$6,C$3) -> 14649.341 | D8: =SUMIFS(Mensal!$C$20:$BJ$20,Mensal!$C$6:$BJ$6,D$3) -> 103736.39 | E8: =SUMIFS(Mensal!$C$20:$BJ$20,Mensal!$C$6:$BJ$6,E$3) -> 303443.64 | F8: =SUMIFS(Mensal!$C$20:$BJ$20,Mensal!$C$6:$BJ$6,F$3) -> 589785.18
A9: Licenças para consultores | B9: =SUMIFS(Mensal!$C$21:$BJ$21,Mensal!$C$6:$BJ$6,B$3) -> 0 | C9: =SUMIFS(Mensal!$C$21:$BJ$21,Mensal!$C$6:$BJ$6,C$3) -> 49140 | D9: =SUMIFS(Mensal!$C$21:$BJ$21,Mensal!$C$6:$BJ$6,D$3) -> 198450 | E9: =SUMIFS(Mensal!$C$21:$BJ$21,Mensal!$C$6:$BJ$6,E$3) -> 462586.95 | F9: =SUMIFS(Mensal!$C$21:$BJ$21,Mensal!$C$6:$BJ$6,F$3) -> 857661.21
A10: Evento anual | B10: =SUMIFS(Mensal!$C$22:$BJ$22,Mensal!$C$6:$BJ$6,B$3) -> 0 | C10: =SUMIFS(Mensal!$C$22:$BJ$22,Mensal!$C$6:$BJ$6,C$3) -> 60000 | D10: =SUMIFS(Mensal!$C$22:$BJ$22,Mensal!$C$6:$BJ$6,D$3) -> 120000 | E10: =SUMIFS(Mensal!$C$22:$BJ$22,Mensal!$C$6:$BJ$6,E$3) -> 200000 | F10: =SUMIFS(Mensal!$C$22:$BJ$22,Mensal!$C$6:$BJ$6,F$3) -> 280000
A11: Patrocínios e convênios | B11: =SUMIFS(Mensal!$C$23:$BJ$23,Mensal!$C$6:$BJ$6,B$3) -> 0 | C11: =SUMIFS(Mensal!$C$23:$BJ$23,Mensal!$C$6:$BJ$6,C$3) -> 120000 | D11: =SUMIFS(Mensal!$C$23:$BJ$23,Mensal!$C$6:$BJ$6,D$3) -> 360000 | E11: =SUMIFS(Mensal!$C$23:$BJ$23,Mensal!$C$6:$BJ$6,E$3) -> 600000 | F11: =SUMIFS(Mensal!$C$23:$BJ$23,Mensal!$C$6:$BJ$6,F$3) -> 900000
A12: Receita bruta | B12: =SUMIFS(Mensal!$C$24:$BJ$24,Mensal!$C$6:$BJ$6,B$3) -> 211978.31 | C12: =SUMIFS(Mensal!$C$24:$BJ$24,Mensal!$C$6:$BJ$6,C$3) -> 2112546.3 | D12: =SUMIFS(Mensal!$C$24:$BJ$24,Mensal!$C$6:$BJ$6,D$3) -> 5960104.4 | E12: =SUMIFS(Mensal!$C$24:$BJ$24,Mensal!$C$6:$BJ$6,E$3) -> 11459587 | F12: =SUMIFS(Mensal!$C$24:$BJ$24,Mensal!$C$6:$BJ$6,F$3) -> 18222251
A13: (-) Tributos sobre a receita | B13: =SUMIFS(Mensal!$C$25:$BJ$25,Mensal!$C$6:$BJ$6,B$3) -> -12718.698 | C13: =SUMIFS(Mensal!$C$25:$BJ$25,Mensal!$C$6:$BJ$6,C$3) -> -169003.7 | D13: =SUMIFS(Mensal!$C$25:$BJ$25,Mensal!$C$6:$BJ$6,D$3) -> -774813.57 | E13: =SUMIFS(Mensal!$C$25:$BJ$25,Mensal!$C$6:$BJ$6,E$3) -> -1604342.2 | F13: =SUMIFS(Mensal!$C$25:$BJ$25,Mensal!$C$6:$BJ$6,F$3) -> -2551115.2
A14: Receita líquida | B14: =SUMIFS(Mensal!$C$26:$BJ$26,Mensal!$C$6:$BJ$6,B$3) -> 199259.61 | C14: =SUMIFS(Mensal!$C$26:$BJ$26,Mensal!$C$6:$BJ$6,C$3) -> 1943542.6 | D14: =SUMIFS(Mensal!$C$26:$BJ$26,Mensal!$C$6:$BJ$6,D$3) -> 5185290.8 | E14: =SUMIFS(Mensal!$C$26:$BJ$26,Mensal!$C$6:$BJ$6,E$3) -> 9855244.8 | F14: =SUMIFS(Mensal!$C$26:$BJ$26,Mensal!$C$6:$BJ$6,F$3) -> 15671136
A15: (-) Infraestrutura variável | B15: =SUMIFS(Mensal!$C$35:$BJ$35,Mensal!$C$6:$BJ$6,B$3) -> -8842.4704 | C15: =SUMIFS(Mensal!$C$35:$BJ$35,Mensal!$C$6:$BJ$6,C$3) -> -87896.045 | D15: =SUMIFS(Mensal!$C$35:$BJ$35,Mensal!$C$6:$BJ$6,D$3) -> -259340.96 | E15: =SUMIFS(Mensal!$C$35:$BJ$35,Mensal!$C$6:$BJ$6,E$3) -> -505739.4 | F15: =SUMIFS(Mensal!$C$35:$BJ$35,Mensal!$C$6:$BJ$6,F$3) -> -804252.51
A16: (-) Mensageria | B16: =SUMIFS(Mensal!$C$36:$BJ$36,Mensal!$C$6:$BJ$6,B$3) -> -3536.9882 | C16: =SUMIFS(Mensal!$C$36:$BJ$36,Mensal!$C$6:$BJ$6,C$3) -> -35158.418 | D16: =SUMIFS(Mensal!$C$36:$BJ$36,Mensal!$C$6:$BJ$6,D$3) -> -103736.39 | E16: =SUMIFS(Mensal!$C$36:$BJ$36,Mensal!$C$6:$BJ$6,E$3) -> -202295.76 | F16: =SUMIFS(Mensal!$C$36:$BJ$36,Mensal!$C$6:$BJ$6,F$3) -> -321701.01
A17: (-) Infraestrutura fixa | B17: =SUMIFS(Mensal!$C$37:$BJ$37,Mensal!$C$6:$BJ$6,B$3) -> -48000 | C17: =SUMIFS(Mensal!$C$37:$BJ$37,Mensal!$C$6:$BJ$6,C$3) -> -50400 | D17: =SUMIFS(Mensal!$C$37:$BJ$37,Mensal!$C$6:$BJ$6,D$3) -> -52920 | E17: =SUMIFS(Mensal!$C$37:$BJ$37,Mensal!$C$6:$BJ$6,E$3) -> -55566 | F17: =SUMIFS(Mensal!$C$37:$BJ$37,Mensal!$C$6:$BJ$6,F$3) -> -58344.3
A18: (-) Equipe de suporte e sucesso | B18: =SUMIFS(Mensal!$C$38:$BJ$38,Mensal!$C$6:$BJ$6,B$3) -> -243000 | C18: =SUMIFS(Mensal!$C$38:$BJ$38,Mensal!$C$6:$BJ$6,C$3) -> -540225 | D18: =SUMIFS(Mensal!$C$38:$BJ$38,Mensal!$C$6:$BJ$6,D$3) -> -1069425 | E18: =SUMIFS(Mensal!$C$38:$BJ$38,Mensal!$C$6:$BJ$6,E$3) -> -1790267.1 | F18: =SUMIFS(Mensal!$C$38:$BJ$38,Mensal!$C$6:$BJ$6,F$3) -> -2510020.4
A19: (-) Ferramentas de suporte | B19: =SUMIFS(Mensal!$C$39:$BJ$39,Mensal!$C$6:$BJ$6,B$3) -> -8164.7953 | C19: =SUMIFS(Mensal!$C$39:$BJ$39,Mensal!$C$6:$BJ$6,C$3) -> -31650.867 | D19: =SUMIFS(Mensal!$C$39:$BJ$39,Mensal!$C$6:$BJ$6,D$3) -> -76223.304 | E19: =SUMIFS(Mensal!$C$39:$BJ$39,Mensal!$C$6:$BJ$6,E$3) -> -138510.15 | F19: =SUMIFS(Mensal!$C$39:$BJ$39,Mensal!$C$6:$BJ$6,F$3) -> -209207.69
A20: Custo dos serviços | B20: =SUMIFS(Mensal!$C$40:$BJ$40,Mensal!$C$6:$BJ$6,B$3) -> -311544.25 | C20: =SUMIFS(Mensal!$C$40:$BJ$40,Mensal!$C$6:$BJ$6,C$3) -> -745330.33 | D20: =SUMIFS(Mensal!$C$40:$BJ$40,Mensal!$C$6:$BJ$6,D$3) -> -1561645.7 | E20: =SUMIFS(Mensal!$C$40:$BJ$40,Mensal!$C$6:$BJ$6,E$3) -> -2692378.4 | F20: =SUMIFS(Mensal!$C$40:$BJ$40,Mensal!$C$6:$BJ$6,F$3) -> -3903525.9
A21: Lucro bruto | B21: =SUMIFS(Mensal!$C$41:$BJ$41,Mensal!$C$6:$BJ$6,B$3) -> -112284.65 | C21: =SUMIFS(Mensal!$C$41:$BJ$41,Mensal!$C$6:$BJ$6,C$3) -> 1198212.2 | D21: =SUMIFS(Mensal!$C$41:$BJ$41,Mensal!$C$6:$BJ$6,D$3) -> 3623645.1 | E21: =SUMIFS(Mensal!$C$41:$BJ$41,Mensal!$C$6:$BJ$6,E$3) -> 7162866.4 | F21: =SUMIFS(Mensal!$C$41:$BJ$41,Mensal!$C$6:$BJ$6,F$3) -> 11767610
A22: Margem bruta (% da receita líquida) | B22: =IFERROR(B21/B14,0) -> -0.56350932 | C22: =IFERROR(C21/C14,0) -> 0.61650939 | D22: =IFERROR(D21/D14,0) -> 0.69883162 | E22: =IFERROR(E21/E14,0) -> 0.72680756 | F22: =IFERROR(F21/F14,0) -> 0.75090983
A23: (-) Equipe fixa (direção, tecnologia, produto, dados, zootecnia, vendas, marketing, administrativo) | B23: =SUMIFS(Mensal!$C$52:$BJ$52,Mensal!$C$6:$BJ$6,B$3) -> -1296000 | C23: =SUMIFS(Mensal!$C$52:$BJ$52,Mensal!$C$6:$BJ$6,C$3) -> -2104200 | D23: =SUMIFS(Mensal!$C$52:$BJ$52,Mensal!$C$6:$BJ$6,D$3) -> -2209410 | E23: =SUMIFS(Mensal!$C$52:$BJ$52,Mensal!$C$6:$BJ$6,E$3) -> -2833866 | F23: =SUMIFS(Mensal!$C$52:$BJ$52,Mensal!$C$6:$BJ$6,F$3) -> -3923654.2
A24: (-) Comissões de vendas | B24: =SUMIFS(Mensal!$C$53:$BJ$53,Mensal!$C$6:$BJ$6,B$3) -> -32451.84 | C24: =SUMIFS(Mensal!$C$53:$BJ$53,Mensal!$C$6:$BJ$6,C$3) -> -181730.3 | D24: =SUMIFS(Mensal!$C$53:$BJ$53,Mensal!$C$6:$BJ$6,D$3) -> -318028.03 | E24: =SUMIFS(Mensal!$C$53:$BJ$53,Mensal!$C$6:$BJ$6,E$3) -> -434108.26 | F24: =SUMIFS(Mensal!$C$53:$BJ$53,Mensal!$C$6:$BJ$6,F$3) -> -525938.86
A25: (-) Aquisição (custo variável) | B25: =SUMIFS(Mensal!$C$54:$BJ$54,Mensal!$C$6:$BJ$6,B$3) -> -67500 | C25: =SUMIFS(Mensal!$C$54:$BJ$54,Mensal!$C$6:$BJ$6,C$3) -> -378000 | D25: =SUMIFS(Mensal!$C$54:$BJ$54,Mensal!$C$6:$BJ$6,D$3) -> -661500 | E25: =SUMIFS(Mensal!$C$54:$BJ$54,Mensal!$C$6:$BJ$6,E$3) -> -902947.5 | F25: =SUMIFS(Mensal!$C$54:$BJ$54,Mensal!$C$6:$BJ$6,F$3) -> -1093955.6
A26: (-) Marketing fixo | B26: =SUMIFS(Mensal!$C$55:$BJ$55,Mensal!$C$6:$BJ$6,B$3) -> -50000 | C26: =SUMIFS(Mensal!$C$55:$BJ$55,Mensal!$C$6:$BJ$6,C$3) -> -151200 | D26: =SUMIFS(Mensal!$C$55:$BJ$55,Mensal!$C$6:$BJ$6,D$3) -> -264600 | E26: =SUMIFS(Mensal!$C$55:$BJ$55,Mensal!$C$6:$BJ$6,E$3) -> -388962 | F26: =SUMIFS(Mensal!$C$55:$BJ$55,Mensal!$C$6:$BJ$6,F$3) -> -525098.7
A27: (-) Custo do evento | B27: =SUMIFS(Mensal!$C$56:$BJ$56,Mensal!$C$6:$BJ$6,B$3) -> 0 | C27: =SUMIFS(Mensal!$C$56:$BJ$56,Mensal!$C$6:$BJ$6,C$3) -> -55000 | D27: =SUMIFS(Mensal!$C$56:$BJ$56,Mensal!$C$6:$BJ$6,D$3) -> -90000 | E27: =SUMIFS(Mensal!$C$56:$BJ$56,Mensal!$C$6:$BJ$6,E$3) -> -140000 | F27: =SUMIFS(Mensal!$C$56:$BJ$56,Mensal!$C$6:$BJ$6,F$3) -> -190000
A28: (-) Gerais e administrativas | B28: =SUMIFS(Mensal!$C$57:$BJ$57,Mensal!$C$6:$BJ$6,B$3) -> -144000 | C28: =SUMIFS(Mensal!$C$57:$BJ$57,Mensal!$C$6:$BJ$6,C$3) -> -201600 | D28: =SUMIFS(Mensal!$C$57:$BJ$57,Mensal!$C$6:$BJ$6,D$3) -> -291060 | E28: =SUMIFS(Mensal!$C$57:$BJ$57,Mensal!$C$6:$BJ$6,E$3) -> -388962 | F28: =SUMIFS(Mensal!$C$57:$BJ$57,Mensal!$C$6:$BJ$6,F$3) -> -495926.55
A29: (-) Itens pontuais | B29: =SUMIFS(Mensal!$C$58:$BJ$58,Mensal!$C$6:$BJ$6,B$3) -> -136000 | C29: =SUMIFS(Mensal!$C$58:$BJ$58,Mensal!$C$6:$BJ$6,C$3) -> -20000 | D29: =SUMIFS(Mensal!$C$58:$BJ$58,Mensal!$C$6:$BJ$6,D$3) -> -20000 | E29: =SUMIFS(Mensal!$C$58:$BJ$58,Mensal!$C$6:$BJ$6,E$3) -> -20000 | F29: =SUMIFS(Mensal!$C$58:$BJ$58,Mensal!$C$6:$BJ$6,F$3) -> -20000
A30: Despesas operacionais | B30: =SUMIFS(Mensal!$C$59:$BJ$59,Mensal!$C$6:$BJ$6,B$3) -> -1725951.8 | C30: =SUMIFS(Mensal!$C$59:$BJ$59,Mensal!$C$6:$BJ$6,C$3) -> -3091730.3 | D30: =SUMIFS(Mensal!$C$59:$BJ$59,Mensal!$C$6:$BJ$6,D$3) -> -3854598 | E30: =SUMIFS(Mensal!$C$59:$BJ$59,Mensal!$C$6:$BJ$6,E$3) -> -5108845.8 | F30: =SUMIFS(Mensal!$C$59:$BJ$59,Mensal!$C$6:$BJ$6,F$3) -> -6774573.9
A31: EBITDA / resultado líquido | B31: =SUMIFS(Mensal!$C$60:$BJ$60,Mensal!$C$6:$BJ$6,B$3) -> -1838236.5 | C31: =SUMIFS(Mensal!$C$60:$BJ$60,Mensal!$C$6:$BJ$6,C$3) -> -1893518.1 | D31: =SUMIFS(Mensal!$C$60:$BJ$60,Mensal!$C$6:$BJ$6,D$3) -> -230952.89 | E31: =SUMIFS(Mensal!$C$60:$BJ$60,Mensal!$C$6:$BJ$6,E$3) -> 2054020.7 | F31: =SUMIFS(Mensal!$C$60:$BJ$60,Mensal!$C$6:$BJ$6,F$3) -> 4993036.3
A32: Margem EBITDA (% da receita líquida) | B32: =IFERROR(B31/B14,0) -> -9.2253343 | C32: =IFERROR(C31/C14,0) -> -0.97426117 | D32: =IFERROR(D31/D14,0) -> -0.044540006 | E32: =IFERROR(E31/E14,0) -> 0.20841904 | F32: =IFERROR(F31/F14,0) -> 0.31861355
A33: FLUXO DE CAIXA
A34: EBITDA | B34: =B31 -> -1838236.5 | C34: =C31 -> -1893518.1 | D34: =D31 -> -230952.89 | E34: =E31 -> 2054020.7 | F34: =F31 -> 4993036.3
A35: Variação do capital de giro | B35: =SUMIFS(Mensal!$C$66:$BJ$66,Mensal!$C$6:$BJ$6,B$3) -> 102001.12 | C35: =SUMIFS(Mensal!$C$66:$BJ$66,Mensal!$C$6:$BJ$6,C$3) -> 39563.951 | D35: =SUMIFS(Mensal!$C$66:$BJ$66,Mensal!$C$6:$BJ$6,D$3) -> -5087.6754 | E35: =SUMIFS(Mensal!$C$66:$BJ$66,Mensal!$C$6:$BJ$6,E$3) -> -4169.7514 | F35: =SUMIFS(Mensal!$C$66:$BJ$66,Mensal!$C$6:$BJ$6,F$3) -> -17092.714
A36: Fluxo de caixa operacional (antes de aportes) | B36: =SUMIFS(Mensal!$C$67:$BJ$67,Mensal!$C$6:$BJ$6,B$3) -> -1736235.4 | C36: =SUMIFS(Mensal!$C$67:$BJ$67,Mensal!$C$6:$BJ$6,C$3) -> -1853954.1 | D36: =SUMIFS(Mensal!$C$67:$BJ$67,Mensal!$C$6:$BJ$6,D$3) -> -236040.56 | E36: =SUMIFS(Mensal!$C$67:$BJ$67,Mensal!$C$6:$BJ$6,E$3) -> 2049850.9 | F36: =SUMIFS(Mensal!$C$67:$BJ$67,Mensal!$C$6:$BJ$6,F$3) -> 4975943.6
A37: Aportes de capital | B37: =SUMIFS(Mensal!$C$69:$BJ$69,Mensal!$C$6:$BJ$6,B$3) -> 3760000 | C37: =SUMIFS(Mensal!$C$69:$BJ$69,Mensal!$C$6:$BJ$6,C$3) -> 940000 | D37: =SUMIFS(Mensal!$C$69:$BJ$69,Mensal!$C$6:$BJ$6,D$3) -> 0 | E37: =SUMIFS(Mensal!$C$69:$BJ$69,Mensal!$C$6:$BJ$6,E$3) -> 0 | F37: =SUMIFS(Mensal!$C$69:$BJ$69,Mensal!$C$6:$BJ$6,F$3) -> 0
A38: Variação líquida de caixa | B38: =B36+B37 -> 2023764.6 | C38: =C36+C37 -> -913954.11 | D38: =D36+D37 -> -236040.56 | E38: =E36+E37 -> 2049850.9 | F38: =F36+F37 -> 4975943.6
A39: Caixa final (com aportes) | B39: =INDEX(Mensal!$C$70:$BJ$70,1,12*B$3) -> 2023764.6 | C39: =INDEX(Mensal!$C$70:$BJ$70,1,12*C$3) -> 1109810.5 | D39: =INDEX(Mensal!$C$70:$BJ$70,1,12*D$3) -> 873769.96 | E39: =INDEX(Mensal!$C$70:$BJ$70,1,12*E$3) -> 2923620.9 | F39: =INDEX(Mensal!$C$70:$BJ$70,1,12*F$3) -> 7899564.4
A40: Caixa acumulado antes de aportes | B40: =INDEX(Mensal!$C$68:$BJ$68,1,12*B$3) -> -1736235.4 | C40: =INDEX(Mensal!$C$68:$BJ$68,1,12*C$3) -> -3590189.5 | D40: =INDEX(Mensal!$C$68:$BJ$68,1,12*D$3) -> -3826230 | E40: =INDEX(Mensal!$C$68:$BJ$68,1,12*E$3) -> -1776379.1 | F40: =INDEX(Mensal!$C$68:$BJ$68,1,12*F$3) -> 3199564.4
A41: BALANÇO PROJETADO (fim do ano)
...

Sheet Retornos
A1: Retornos, break-even, necessidade de caixa e investimento por fase
A3: Indicador | B3: Valor | C3: Observação
A4: Necessidade máxima de caixa (queima acumulada antes de aportes) | B4: =-MIN(Mensal!$C$68:$BJ$68) -> 4044057.4 | C4: Pico negativo do caixa acumulado.
A5: Aporte solicitado | B5: =ask -> 4700000 | C5: Premissa (decisão da diretoria).
A6: Folga do aporte sobre a necessidade | B6: =IFERROR(ask/B4-1,0) -> 0.16219912 | C6: Colchão para atrasos de vendas.
A7: Caixa mínimo com aportes | B7: =MIN(Mensal!$C$70:$BJ$70) -> 489402.22 | C7: Negativo = falta de caixa neste cenário.
A8: Mês do ponto mínimo (antes de aportes) | B8: =MATCH(MIN(Mensal!$C$68:$BJ$68),Mensal!$C$68:$BJ$68,0) -> 31
A9: Break-even operacional (1º mês com EBITDA positivo) | B9: =IFERROR(MATCH(1,Mensal!$C$71:$BJ$71,0),"> 60") -> 32 | C9: Mês do plano.
A10: Payback do investimento (caixa acumulado volta a zero) | B10: =IFERROR(MATCH(1,Mensal!$C$72:$BJ$72,0),"> 60") -> 54 | C10: Mês do plano; "> 60" = não ocorre em 5 anos.
A12: Fluxo de caixa livre (antes de aportes) | B12: Ano 1 | C12: Ano 2 | D12: Ano 3 | E12: Ano 4 | F12: Ano 5
A13: Fluxo operacional do ano | B13: =Anual!B36 -> -1736235.4 | C13: =Anual!C36 -> -1853954.1 | D13: =Anual!D36 -> -236040.56 | E13: =Anual!E36 -> 2049850.9 | F13: =Anual!F36 -> 4975943.6
A14: (+) Valor residual no ano 5 (múltiplo x receita líquida) | B14: 0 | C14: 0 | D14: 0 | E14: 0 | F14: =tv_mult*Anual!F14 -> 23506704
A15: Fluxo com valor residual | B15: =B13+B14 -> -1736235.4 | C15: =C13+C14 -> -1853954.1 | D15: =D13+D14 -> -236040.56 | E15: =E13+E14 -> 2049850.9 | F15: =F13+F14 -> 28482648
A17: VPL sem valor residual (a TMA) | B17: =NPV(disc,B13:F13) -> -226235.57 | C17: Desconto anual, fluxos no fim de cada ano.
A18: VPL com valor residual (a TMA) | B18: =NPV(disc,B15:F15) -> 7476441.2
A19: TIR sem valor residual | B19: =IFERROR(IRR(B13:F13),"n/d") -> 0.21547458 | C19: "n/d" = fluxos sem inversão de sinal.
A20: TIR com valor residual | B20: =IFERROR(IRR(B15:F15),"n/d") -> 0.84007865
A22: Investimento (consumo de caixa) por fase | B22: Mês inicial | C22: Mês final | D22: Consumo(-)/geração(+) de caixa | E22: Fazendas ao fim da fase | F22: ARR ao fim da fase
A23: Fase 1 - Fundação e pilotos (M1-M6) | B23: 1 | C23: 6 | D23: =SUMIFS(Mensal!$C$67:$BJ$67,Mensal!$C$5:$BJ$5,">="&B23,Mensal!$C$5:$BJ$5,"<="&C23) -> -829857.18 | E23: =INDEX(Mensal!$C$11:$BJ$11,1,C23) -> 8.892432 | F23: =INDEX(Mensal!$C$27:$BJ$27,1,C23)*12 -> 111601.52
A24: Fase 2 - Lançamento comercial (M7-M18) | B24: 7 | C24: 18 | D24: =SUMIFS(Mensal!$C$67:$BJ$67,Mensal!$C$5:$BJ$5,">="&B24,Mensal!$C$5:$BJ$5,"<="&C24) -> -2001899 | E24: =INDEX(Mensal!$C$11:$BJ$11,1,C24) -> 93.815355 | F24: =INDEX(Mensal!$C$27:$BJ$27,1,C24)*12 -> 1611357.6
A25: Fase 3 - Escala regional (M19-M36) | B25: 19 | C25: 36 | D25: =SUMIFS(Mensal!$C$67:$BJ$67,Mensal!$C$5:$BJ$5,">="&B25,Mensal!$C$5:$BJ$5,"<="&C25) -> -994473.9 | E25: =INDEX(Mensal!$C$11:$BJ$11,1,C25) -> 360.71905 | F25: =INDEX(Mensal!$C$27:$BJ$27,1,C25)*12 -> 6923404.6
A26: Fase 4 - Expansão e plataforma (M37-M60) | B26: 37 | C26: 60 | D26: =SUMIFS(Mensal!$C$67:$BJ$67,Mensal!$C$5:$BJ$5,">="&B26,Mensal!$C$5:$BJ$5,"<="&C26) -> 7025794.5 | E26: =INDEX(Mensal!$C$11:$BJ$11,1,C26) -> 859.94847 | F26: =INDEX(Mensal!$C$27:$BJ$27,1,C26)*12 -> 19456171
A27: Total | D27: =SUM(D23:D26) -> 3199564.4

Sheet Suporte
A1: Suporte e Sucesso do Cliente: dimensionamento por fazendas e vacas
A2: Valores do ano 1 (sem reajuste). Edite as fazendas em azul; a equipe, o custo e a margem escalam por fórmula usando as razões da aba Premissas.
A4: Dimensionamento (mensal) | B4: Cenário A | C4: Cenário B | D4: Cenário C | E4: Cenário D | F4: Cenário E | G4: Cenário F
A5: Fazendas ativas | B5: 25 | C5: 50 | D5: 100 | E5: 200 | F5: 400 | G5: 800
A6: Vacas atendidas | B6: =B5*herd_avg -> 4250 | C6: =C5*herd_avg -> 8500 | D6: =D5*herd_avg -> 17000 | E6: =E5*herd_avg -> 34000 | F6: =F5*herd_avg -> 68000 | G6: =G5*herd_avg -> 136000
A7: Novas fazendas por mês (premissa: 5% da base) | B7: =B5*0.05 -> 1.25 | C7: =C5*0.05 -> 2.5 | D7: =D5*0.05 -> 5 | E7: =E5*0.05 -> 10 | F7: =F5*0.05 -> 20 | G7: =G5*0.05 -> 40
A8: Atendentes N1 | B8: =IF(B5<n1_from,0,ROUNDUP(B5/r_n1,0)) -> 0 | C8: =IF(C5<n1_from,0,ROUNDUP(C5/r_n1,0)) -> 1 | D8: =IF(D5<n1_from,0,ROUNDUP(D5/r_n1,0)) -> 1 | E8: =IF(E5<n1_from,0,ROUNDUP(E5/r_n1,0)) -> 2 | F8: =IF(F5<n1_from,0,ROUNDUP(F5/r_n1,0)) -> 3 | G8: =IF(G5<n1_from,0,ROUNDUP(G5/r_n1,0)) -> 6
A9: Gerentes de sucesso (CS) | B9: =MAX(1,ROUNDUP(B5/r_cs,0)) -> 1 | C9: =MAX(1,ROUNDUP(C5/r_cs,0)) -> 1 | D9: =MAX(1,ROUNDUP(D5/r_cs,0)) -> 1 | E9: =MAX(1,ROUNDUP(E5/r_cs,0)) -> 2 | F9: =MAX(1,ROUNDUP(F5/r_cs,0)) -> 4 | G9: =MAX(1,ROUNDUP(G5/r_cs,0)) -> 8
A10: Analistas zootécnicos/vet N2 | B10: =ROUNDUP(B6/r_n2,0) -> 1 | C10: =ROUNDUP(C6/r_n2,0) -> 1 | D10: =ROUNDUP(D6/r_n2,0) -> 1 | E10: =ROUNDUP(E6/r_n2,0) -> 2 | F10: =ROUNDUP(F6/r_n2,0) -> 3 | G10: =ROUNDUP(G6/r_n2,0) -> 5
A11: Especialistas de implantação | B11: =ROUNDUP(B7/r_onb,0) -> 1 | C11: =ROUNDUP(C7/r_onb,0) -> 1 | D11: =ROUNDUP(D7/r_onb,0) -> 1 | E11: =ROUNDUP(E7/r_onb,0) -> 2 | F11: =ROUNDUP(F7/r_onb,0) -> 3 | G11: =ROUNDUP(G7/r_onb,0) -> 5
A12: Total de pessoas em suporte e sucesso | B12: =SUM(B8:B11) -> 3 | C12: =SUM(C8:C11) -> 4 | D12: =SUM(D8:D11) -> 4 | E12: =SUM(E8:E11) -> 8 | F12: =SUM(F8:F11) -> 13 | G12: =SUM(G8:G11) -> 24
A13: Custo da equipe | B13: =B8*c_n1+B9*c_cs+B10*c_n2+B11*c_onb -> 27000 | C13: =C8*c_n1+C9*c_cs+C10*c_n2+C11*c_onb -> 31500 | D13: =D8*c_n1+D9*c_cs+D10*c_n2+D11*c_onb -> 31500 | E13: =E8*c_n1+E9*c_cs+E10*c_n2+E11*c_onb -> 63000 | F13: =F8*c_n1+F9*c_cs+F10*c_n2+F11*c_onb -> 102500 | G13: =G8*c_n1+G9*c_cs+G10*c_n2+G11*c_onb -> 186000
A14: Custo de ferramentas | B14: =B12*tool_seat+B5*tool_farm -> 1050 | C14: =C12*tool_seat+C5*tool_farm -> 1600 | D14: =D12*tool_seat+D5*tool_farm -> 2200 | E14: =E12*tool_seat+E5*tool_farm -> 4400 | F14: =F12*tool_seat+F5*tool_farm -> 8050 | G14: =G12*tool_seat+G5*tool_farm -> 15600
A15: Infra e mensageria por fazenda (variável) | B15: =B5*(infra_var+msg) -> 2625 | C15: =C5*(infra_var+msg) -> 5250 | D15: =D5*(infra_var+msg) -> 10500 | E15: =E5*(infra_var+msg) -> 21000 | F15: =F5*(infra_var+msg) -> 42000 | G15: =G5*(infra_var+msg) -> 84000
A16: Custo total de suporte, sucesso e operação por cliente | B16: =B13+B14+B15 -> 30675 | C16: =C13+C14+C15 -> 38350 | D16: =D13+D14+D15 -> 44200 | E16: =E13+E14+E15 -> 88400 | F16: =F13+F14+F15 -> 152550 | G16: =G13+G14+G15 -> 285600
A17: Custo por fazenda/mês | B17: =B16/B5 -> 1227 | C17: =C16/C5 -> 767 | D17: =D16/D5 -> 442 | E17: =E16/E5 -> 442 | F17: =F16/F5 -> 381.375 | G17: =G16/G5 -> 357
A18: Custo por vaca/mês | B18: =B16/B6 -> 7.2176471 | C18: =C16/C6 -> 4.5117647 | D18: =D16/D6 -> 2.6 | E18: =E16/E6 -> 2.6 | F18: =F16/F6 -> 2.2433824 | G18: =G16/G6 -> 2.1
A19: Receita de assinatura por fazenda/mês (ARPA) | B19: =arpa_base -> 1252 | C19: =arpa_base -> 1252 | D19: =arpa_base -> 1252 | E19: =arpa_base -> 1252 | F19: =arpa_base -> 1252 | G19: =arpa_base -> 1252
A20: Custo de suporte e operação (% da assinatura) | B20: =B17/B19 -> 0.98003195 | C20: =C17/C19 -> 0.61261981 | D20: =D17/D19 -> 0.35303514 | E20: =E17/E19 -> 0.35303514 | F20: =F17/F19 -> 0.30461262 | G20: =G17/G19 -> 0.28514377
A21: Fazendas por pessoa de suporte e sucesso | B21: =B5/B12 -> 8.3333333 | C21: =C5/C12 -> 12.5 | D21: =D5/D12 -> 25 | E21: =E5/E12 -> 25 | F21: =F5/F12 -> 30.769231 | G21: =G5/G12 -> 33.333333
A23: Nota: a linha "Custo total ... por cliente" inclui N1, CS, N2, implantação, ferramentas, infraestrutura e mensageria; as despesas de N3 (engenharia) estão no time de desenvolvimento.
A25: SLAs POR PLANO (horário de atendimento e prazos)
A26: Item | B26: Essencial | C26: Profissional | D26: Premium
A27: Canais | B27: Chat no app, e-mail, base de conhecimento | C27: + WhatsApp | D27: + telefone e WhatsApp prioritário, gerente de sucesso dedicado
A28: Horário de atendimento | B28: Seg-Sex 8h-18h | C28: Seg-Sáb 6h-19h | D28: Seg-Sáb 6h-20h + plantão P1 24x7
A29: P1 Crítica (sistema fora do ar / dados incorretos): 1ª resposta | B29: 4 h úteis | C29: 1 h | D29: 30 min (24x7)
A30: P1 Crítica: meta de resolução | B30: 24 h | C30: 8 h | D30: 4 h
A31: P2 Alta (função principal degradada, importação falha): 1ª resposta | B31: 8 h úteis | C31: 4 h | D31: 2 h
A32: P2 Alta: meta de resolução | B32: 3 dias úteis | C32: 2 dias úteis | D32: 1 dia útil
A33: P3 Média (dúvida de uso, falha com contorno): 1ª resposta | B33: 1 dia útil | C33: 8 h | D33: 4 h
A34: P3 Média: meta de resolução | B34: 5 dias úteis | C34: 3 dias úteis | D34: 2 dias úteis
A35: P4 Baixa (sugestão, melhoria): 1ª resposta | B35: 2 dias úteis | C35: 1 dia útil | D35: 8 h
A36: Revisão de resultados com CS | B36: Trimestral (coletiva) | C36: Trimestral (individual) | D36: Mensal (individual)
A37: Apoio zootécnico/veterinário (N2) | B37: Sob demanda, via e-mail | C37: 2 consultas/mês | D37: Ilimitado + revisão mensal de protocolo
A38: Disponibilidade-alvo da plataforma | B38: 99,5% | C38: 99,7% | D38: 99,9%

Sheet Cenários e sensibilidade
A1: Cenários e sensibilidade (valores gerados pelo modelo)
A2: Valores colados a partir de execuções do modelo com o seletor de cenário (1/2/3) e fatores de sensibilidade. Mesmo aporte solicitado em todos os cenários. Reexecute para atualizar após mudar premissas.
A4: Indicador | B4: Conservador | C4: Base | D4: Otimista
A5: Fazendas ativas (fim do ano 3) | B5: 205.84354 | C5: 360.71905 | D5: 524.76415
A6: Fazendas ativas (fim do ano 5) | B6: 473.59393 | C6: 859.94847 | D6: 1286.9562
A7: Vacas atendidas (ano 5) | B7: 80510.968 | C7: 146191.24 | D7: 218782.55
A8: ARR (ano 3, R$) | B8: 4064441.7 | C8: 6923404.6 | D8: 9771924.9
A9: ARR (ano 5, R$) | B9: 11171156 | C9: 19456171 | D9: 28131848
A10: Receita líquida ano 3 (R$) | B10: 3123872.1 | C10: 5185290.8 | D10: 7205416.9
A11: Receita líquida ano 5 (R$) | B11: 9177855.6 | C11: 15671136 | D11: 22358941
A12: EBITDA ano 3 (R$) | B12: -1350001.4 | C12: -230952.89 | D12: 815463.27
A13: EBITDA ano 5 (R$) | B13: 696490.66 | C13: 4993036.3 | D13: 9225814
A14: Margem EBITDA ano 5 | B14: 0.075888169 | C14: 0.31861355 | D14: 0.41262304
A15: Margem bruta ano 5 | B15: 0.74171232 | C15: 0.75090983 | D15: 0.74459457
A16: Necessidade máxima de caixa (R$) | B16: 5696925.5 | C16: 4044057.4 | D16: 3423971.7
... A19: Break-even operacional (mês) | B19: 44 | C19: 32 | D19: 28
A20: Payback do investimento (mês) | B20: > 60 | C20: 54 | D20: 45
A21: VPL sem valor residual (R$) | B21: -3377012.5 | C21: -226235.57 | D21: 2848667.4
A22: VPL com valor residual (R$) | B22: 1134087.1 | C22: 7476441.2 | D22: 13838534
A23: TIR sem valor residual | B23: n/d | C23: 0.21547458 | D23: 0.61685394
A24: TIR com valor residual | B24: 0.36246121 | C24: 0.84007865 | D24: 1.1911935
A25: Headcount total (ano 5) | B25: 35 | C25: 44 | D25: 56
A28: Sensibilidade: VPL com valor residual (R$) - preço x churn
A29: Fator de preço \ fator de churn | B29: churn x0.7 | C29: churn x1.0 | D29: churn x1.4
A30: preço x0.8 | B30: 4847715.1 | C30: 4257051.8 | D30: 3512759.3
A31: preço x0.9 | B31: 6536253.6 | C31: 5866746.5 | D31: 5026600.4
A32: preço x1.0 | B32: 8224792.1 | C32: 7476441.2 | D32: 6540441.6
A33: preço x1.1 | B33: 9913330.6 | C33: 9086136 | D33: 8054282.7
A34: preço x1.2 | B34: 11601869 | C34: 10695831 | D34: 9568123.9
A37: Sensibilidade: EBITDA do ano 5 (R$) - preço x churn
A38: Fator de preço \ fator de churn | B38: churn x0.7 | C38: churn x1.0 | D38: churn x1.4
A39: preço x0.8 | B39: 3053741.9 | C39: 2609581.6 | D39: 2037692.7
A40: preço x0.9 | B40: 4316423.4 | C40: 3801309 | D40: 3143985.6
A41: preço x1.0 | B41: 5579104.9 | C41: 4993036.3 | D41: 4250278.5
A42: preço x1.1 | B42: 6841786.4 | C42: 6184763.6 | D42: 5356571.4
A43: preço x1.2 | B43: 8104467.9 | C43: 7376491 | D43: 6462864.3
A46: Sensibilidade: necessidade máxima de caixa (R$) - preço x churn
A47: Fator de preço \ fator de churn | B47: churn x0.7 | C47: churn x1.0 | D47: churn x1.4
A48: preço x0.8 | B48: 4895481.2 | C48: 5007153 | D48: 5192295.4
A49: preço x0.9 | B49: 4382093.4 | C49: 4434279.1 | D49: 4537803.6
...

Sheet Mensal
A1: Motor mensal (somente fórmulas)
A3: Linha | B3: Unid. | C3: M1 | D3: M2 | E3: M3 | F3: M4 | G3: M5 | H3: M6 | I3: M7 | J3: M8 | K3: M9 | L3: M10 | M3: M11 | N3: M12 | O3: M13 | P3: M14 | Q3: M15 | R3: M16 | S3: M17 | T3: M18 | U3: M19 | V3: M20 | W3: M21 | X3: M22 | Y3: M23 | Z3: M24 | AA3: M25 | AB3: M26 | AC3: M27 | AD3: M28 | AE3: M29 | AF3: M30 | AG3: M31 | AH3: M32 | AI3: M33 | AJ3: M34 | AK3: M35 | AL3: M36 | AM3: M37 | AN3: M38 | AO3: M39 | AP3: M40 | AQ3: M41 | AR3: M42 | AS3: M43 | AT3: M44 | AU3: M45 | AV3: M46 | AW3: M47 | AX3: M48 | AY3: M49 | AZ3: M50 | BA3: M51 | BB3: M52 | BC3: M53 | BD3: M54 | BE3: M55 | BF3: M56 | BG3: M57 | BH3: M58 | BI3: M59 | BJ3: M60
A4: Linha do tempo
A5: Mês | B5: # | C5: 1 | D5: =C5+1 -> 2 | E5: =D5+1 -> 3 | F5: =E5+1 -> 4 | G5: =F5+1 -> 5 | H5: =G5+1 -> 6 | I5: =H5+1 -> 7 | J5: =I5+1 -> 8 | K5: =J5+1 -> 9 | ... BJ5: =BI5+1 -> 60
A6: Ano | B6: # | C6: =ROUNDUP(C5/12,0) -> 1 | D6: =ROUNDUP(D5/12,0) -> 1 | E6: =ROUNDUP(E5/12,0) -> 1 | F6: =ROUNDUP(F5/12,0) -> 1 | G6: =ROUNDUP(G5/12,0) -> 1 | H6: =ROUNDUP(H5/12,0) -> 1 | I6: =ROUNDUP(I5/12,0) -> 1 | J6: =ROUNDUP(J5/12,0) -> 1 | ... BJ6: =ROUNDUP(BJ5/12,0) -> 5
A7: Fator de reajuste (IPCA) | B7: x | C7: =(1+reajuste)^(C6-1) -> 1 | D7: =(1+reajuste)^(D6-1) -> 1 | E7: =(1+reajuste)^(E6-1) -> 1 | F7: =(1+reajuste)^(F6-1) -> 1 | G7: =(1+reajuste)^(G6-1) -> 1 | H7: =(1+reajuste)^(H6-1) -> 1 | I7: =(1+reajuste)^(I6-1) -> 1 | J7: =(1+reajuste)^(J6-1) -> 1 | ... BJ7: =(1+reajuste)^(BJ6-1) -> 1.2155063
A8: Clientes (fazendas e vacas)
A9: Novas fazendas | B9: fazendas | C9: =IF(C5<launch_month,0,INDEX(new_farms_y,1,C6)*f_new) -> 0 | D9: =IF(D5<launch_month,0,INDEX(new_farms_y,1,D6)*f_new) -> 0 | E9: =IF(E5<launch_month,0,INDEX(new_farms_y,1,E6)*f_new) -> 0 | F9: =IF(F5<launch_month,0,INDEX(new_farms_y,1,F6)*f_new) -> 3 | G9: =IF(G5<launch_month,0,INDEX(new_farms_y,1,G6)*f_new) -> 3 | H9: =IF(H5<launch_month,0,INDEX(new_farms_y,1,H6)*f_new) -> 3 | I9: =IF(I5<launch_month,0,INDEX(new_farms_y,1,I6)*f_new) -> 3 | J9: =IF(J5<launch_month,0,INDEX(new_farms_y,1,J6)*f_new) -> 3 | ... BJ9: =IF(BJ5<launch_month,0,INDEX(new_farms_y,1,BJ6)*f_new) -> 30
A10: Fazendas perdidas (churn) | B10: fazendas | C10: =0 -> 0 | D10: =C11*churn_m*f_churn*s_churn -> 0 | E10: =D11*churn_m*f_churn*s_churn -> 0 | F10: =E11*churn_m*f_churn*s_churn -> 0 | G10: =F11*churn_m*f_churn*s_churn -> 0.036 | H10: =G11*churn_m*f_churn*s_churn -> 0.071568 | I10: =H11*churn_m*f_churn*s_churn -> 0.10670918 | J10: =I11*churn_m*f_churn*s_churn -> 0.14142867 | K10: =J11*churn_m*f_churn*s_churn -> 0.17573153 | ... BJ10: =BI11*churn_m*f_churn*s_churn -> 10.080346
A11: Fazendas ativas (fim do mês) | B11: fazendas | C11: =C9-C10 -> 0 | D11: =C11+D9-D10 -> 0 | E11: =D11+E9-E10 -> 0 | F11: =E11+F9-F10 -> 3 | G11: =F11+G9-G10 -> 5.964 | H11: =G11+H9-H10 -> 8.892432 | I11: =H11+I9-I10 -> 11.785723 | J11: =I11+J9-J10 -> 14.644294 | K11: =J11+K9-K10 -> 17.468563 | ... BJ11: =BI11+BJ9-BJ10 -> 859.94847
A12: Fazendas ativas (média do mês) | B12: fazendas | C12: =C11/2 -> 0 | D12: =(C11+D11)/2 -> 0 | E12: =(D11+E11)/2 -> 0 | F12: =(E11+F11)/2 -> 1.5 | G12: =(F11+G11)/2 -> 4.482 | H12: =(G11+H11)/2 -> 7.428216 | I12: =(H11+I11)/2 -> 10.339077 | J12: =(I11+J11)/2 -> 13.215008 | K12: =(J11+K11)/2 -> 16.056428 | ... BJ12: =(BI11+BJ11)/2 -> 849.98864
A13: Vacas em lactação atendidas (fim do mês) | B13: vacas | C13: =C11*herd_avg -> 0 | D13: =D11*herd_avg -> 0 | E13: =E11*herd_avg -> 0 | F13: =F11*herd_avg -> 510 | G13: =G11*herd_avg -> 1013.88 | H13: =H11*herd_avg -> 1511.7134 | I13: =I11*herd_avg -> 2003.5729 | J13: =J11*herd_avg -> 2489.53 | ... BJ13: =BJ11*herd_avg -> 146191.24
A14: Licenças de consultor ativas | B14: licenças | C14: =IF(C5<=12,0,INDEX(new_cons_y,1,C6)) -> 0 | D14: =C14+IF(D5<=12,0,INDEX(new_cons_y,1,D6)) -> 0 | E14: =D14+IF(E5<=12,0,INDEX(new_cons_y,1,E6)) -> 0 | F14: =E14+IF(F5<=12,0,INDEX(new_cons_y,1,F6)) -> 0 | G14: =F14+IF(G5<=12,0,INDEX(new_cons_y,1,G6)) -> 0 | H14: =G14+IF(H5<=12,0,INDEX(new_cons_y,1,H6)) -> 0 | I14: =H14+IF(I5<=12,0,INDEX(new_cons_y,1,I6)) -> 0 | J14: =I14+IF(J5<=12,0,INDEX(new_cons_y,1,J6)) -> 0 | K14: =J14+IF(K5<=12,0,INDEX(new_cons_y,1,K6)) -> 0 | ... BJ14: =BI14+IF(BJ5<=12,0,INDEX(new_cons_y,1,BJ6)) -> 120
A15: Mensalidade média por fazenda (com reajuste e cenário) | B15: R$ | C15: =arpa_base*C7*f_price*s_price -> 1252 | D15: =arpa_base*D7*f_price*s_price -> 1252 | E15: =arpa_base*E7*f_price*s_price -> 1252 | F15: =arpa_base*F7*f_price*s_price -> 1252 | G15: =arpa_base*G7*f_price*s_price -> 1252 | H15: =arpa_base*H7*f_price*s_price -> 1252 | I15: =arpa_base*I7*f_price*s_price -> 1252 | J15: =arpa_base*J7*f_price*s_price -> 1252 | ... BJ15: =arpa_base*BJ7*f_price*s_price -> 1521.8138
A16: Receita bruta
A17: Assinatura (por vaca/mês, com mínimo por plano) | B17: R$ | C17: =C12*C15 -> 0 | D17: =D12*D15 -> 0 | E17: =E12*E15 -> 0 | F17: =F12*F15 -> 1878 | G17: =G12*G15 -> 5611.464 | H17: =H12*H15 -> 9300.1264 | I17: =I12*I15 -> 12944.525 | J17: =J12*J15 -> 16545.191 | ... BJ17: =BJ12*BJ15 -> 1293524.5
A18: Implantação (taxa única) | B18: R$ | C18: =C9*setup_avg*C7*f_price*s_price -> 0 | D18: =D9*setup_avg*D7*f_price*s_price -> 0 | E18: =E9*setup_avg*E7*f_price*s_price -> 0 | F18: =F9*setup_avg*F7*f_price*s_price -> 7152 | G18: =G9*setup_avg*G7*f_price*s_price -> 7152 | H18: =H9*setup_avg*H7*f_price*s_price -> 7152 | I18: =I9*setup_avg*I7*f_price*s_price -> 7152 | J18: =J9*setup_avg*J7*f_price*s_price -> 7152 | ... BJ18: =BJ9*setup_avg*BJ7*f_price*s_price -> 86933.007
A19: Módulos premium | B19: R$ | C19: =C12*INDEX(adopt_mod_y,1,C6)*price_mod*C7 -> 0 | D19: =D12*INDEX(adopt_mod_y,1,D6)*price_mod*D7 -> 0 | E19: =E12*INDEX(adopt_mod_y,1,E6)*price_mod*E7 -> 0 | F19: =F12*INDEX(adopt_mod_y,1,F6)*price_mod*F7 -> 0 | G19: =G12*INDEX(adopt_mod_y,1,G6)*price_mod*G7 -> 0 | H19: =H12*INDEX(adopt_mod_y,1,H6)*price_mod*H7 -> 0 | I19: =I12*INDEX(adopt_mod_y,1,I6)*price_mod*I7 -> 0 | J19: =J12*INDEX(adopt_mod_y,1,J6)*price_mod*J7 -> 0 | ... BJ19: =BJ12*INDEX(adopt_mod_y,1,BJ6)*price_mod*BJ7 -> 108482.48
A20: Benchmark premium | B20: R$ | C20: =C12*INDEX(adopt_bench_y,1,C6)*price_bench*C7 -> 0 | D20: =D12*INDEX(adopt_bench_y,1,D6)*price_bench*D7 -> 0 | E20: =E12*INDEX(adopt_bench_y,1,E6)*price_bench*E7 -> 0 | F20: =F12*INDEX(adopt_bench_y,1,F6)*price_bench*F7 -> 0 | G20: =G12*INDEX(adopt_bench_y,1,G6)*price_bench*G7 -> 0 | H20: =H12*INDEX(adopt_bench_y,1,H6)*price_bench*H7 -> 0 | I20: =I12*INDEX(adopt_bench_y,1,I6)*price_bench*I7 -> 0 | J20: =J12*INDEX(adopt_bench_y,1,J6)*price_bench*J7 -> 0 | ... BJ20: =BJ12*INDEX(adopt_bench_y,1,BJ6)*price_bench*BJ7 -> 56824.158
A21: Licenças para consultores | B21: R$ | C21: =C14*price_cons*C7 -> 0 | D21: =D14*price_cons*D7 -> 0 | E21: =E14*price_cons*E7 -> 0 | F21: =F14*price_cons*F7 -> 0 | G21: =G14*price_cons*G7 -> 0 | H21: =H14*price_cons*H7 -> 0 | I21: =I14*price_cons*I7 -> 0 | J21: =J14*price_cons*J7 -> 0 | ... BJ21: =BJ14*price_cons*BJ7 -> 87516.45
A22: Evento anual (ingressos) | B22: R$ | C22: =IF(MOD(C5-1,12)+1=event_month,INDEX(event_rev_y,1,C6),0) -> 0 | D22: =IF(MOD(D5-1,12)+1=event_month,INDEX(event_rev_y,1,D6),0) -> 0 | E22: =IF(MOD(E5-1,12)+1=event_month,INDEX(event_rev_y,1,E6),0) -> 0 | F22: =IF(MOD(F5-1,12)+1=event_month,INDEX(event_rev_y,1,F6),0) -> 0 | G22: =IF(MOD(G5-1,12)+1=event_month,INDEX(event_rev_y,1,G6),0) -> 0 | H22: =IF(MOD(H5-1,12)+1=event_month,INDEX(event_rev_y,1,H6),0) -> 0 | I22: =IF(MOD(I5-1,12)+1=event_month,INDEX(event_rev_y,1,I6),0) -> 0 | J22: =IF(MOD(J5-1,12)+1=event_month,INDEX(event_rev_y,1,J6),0) -> 0 | ... BJ22: =IF(MOD(BJ5-1,12)+1=event_month,INDEX(event_rev_y,1,BJ6),0) -> 0
A23: Patrocínios e convênios | B23: R$ | C23: =INDEX(spons_y,1,C6)/12*IF(C5>=launch_month,1,0) -> 0 | D23: =INDEX(spons_y,1,D6)/12*IF(D5>=launch_month,1,0) -> 0 | E23: =INDEX(spons_y,1,E6)/12*IF(E5>=launch_month,1,0) -> 0 | F23: =INDEX(spons_y,1,F6)/12*IF(F5>=launch_month,1,0) -> 0 | G23: =INDEX(spons_y,1,G6)/12*IF(G5>=launch_month,1,0) -> 0 | H23: =INDEX(spons_y,1,H6)/12*IF(H5>=launch_month,1,0) -> 0 | I23: =INDEX(spons_y,1,I6)/12*IF(I5>=launch_month,1,0) -> 0 | J23: =INDEX(spons_y,1,J6)/12*IF(J5>=launch_month,1,0) -> 0 | ... BJ23: =INDEX(spons_y,1,BJ6)/12*IF(BJ5>=launch_month,1,0) -> 75000
A24: RECEITA BRUTA | B24: R$ | C24: =SUM(C17:C23) -> 0 | D24: =SUM(D17:D23) -> 0 | E24: =SUM(E17:E23) -> 0 | F24: =SUM(F17:F23) -> 9030 | G24: =SUM(G17:G23) -> 12763.464 | H24: =SUM(H17:H23) -> 16452.126 | I24: =SUM(I17:I23) -> 20096.525 | J24: =SUM(J17:J23) -> 23697.191 | ... BJ24: =SUM(BJ17:BJ23) -> 1708280.6
A25: (-) Tributos sobre a receita | B25: R$ | C25: =-C24*INDEX(tax_y,1,C6) -> 0 | D25: =-D24*INDEX(tax_y,1,D6) -> 0 | E25: =-E24*INDEX(tax_y,1,E6) -> 0 | F25: =-F24*INDEX(tax_y,1,F6) -> -541.8 | G25: =-G24*INDEX(tax_y,1,G6) -> -765.80784 | H25: =-H24*INDEX(tax_y,1,H6) -> -987.12759 | I25: =-I24*INDEX(tax_y,1,I6) -> -1205.7915 | J25: =-J24*INDEX(tax_y,1,J6) -> -1421.8314 | ... BJ25: =-BJ24*INDEX(tax_y,1,BJ6) -> -239159.28
A26: RECEITA LÍQUIDA | B26: R$ | C26: =C24+C25 -> 0 | D26: =D24+D25 -> 0 | E26: =E24+E25 -> 0 | F26: =F24+F25 -> 8488.2 | G26: =G24+G25 -> 11997.656 | H26: =H24+H25 -> 15464.999 | I26: =I24+I25 -> 18890.733 | J26: =J24+J25 -> 22275.359 | ... BJ26: =BJ24+BJ25 -> 1469121.3
A27: Memo: receita recorrente do mês (assinatura + módulos + benchmark + consultores + patrocínios) | B27: R$ | C27: =C17+C19+C20+C21+C23 -> 0 | D27: =D17+D19+D20+D21+D23 -> 0 | E27: =E17+E19+E20+E21+E23 -> 0 | F27: =F17+F19+F20+F21+F23 -> 1878 | G27: =G17+G19+G20+G21+G23 -> 5611.464 | H27: =H17+H19+H20+H21+H23 -> 9300.1264 | I27: =I17+I19+I20+I21+I23 -> 12944.525 | J27: =J17+J19+J20+J21+J23 -> 16545.191 | ... BJ27: =BJ17+BJ19+BJ20+BJ21+BJ23 -> 1621347.6
A28: Equipe de suporte e sucesso (dimensionada por fazendas e vacas)
A29: Atendentes N1 | B29: pessoas | C29: =IF(OR(C5<launch_month,C11<n1_from),0,ROUNDUP(C11/r_n1,0)) -> 0 | D29: =IF(OR(D5<launch_month,D11<n1_from),0,ROUNDUP(D11/r_n1,0)) -> 0 | E29: =IF(OR(E5<launch_month,E11<n1_from),0,ROUNDUP(E11/r_n1,0)) -> 0 | F29: =IF(OR(F5<launch_month,F11<n1_from),0,ROUNDUP(F11/r_n1,0)) -> 0 | G29: =IF(OR(G5<launch_month,G11<n1_from),0,ROUNDUP(G11/r_n1,0)) -> 0 | H29: =IF(OR(H5<launch_month,H11<n1_from),0,ROUNDUP(H11/r_n1,0)) -> 0 | I29: =IF(OR(I5<launch_month,I11<n1_from),0,ROUNDUP(I11/r_n1,0)) -> 0 | J29: =IF(OR(J5<launch_month,J11<n1_from),0,ROUNDUP(J11/r_n1,0)) -> 0 | ... BJ29: =IF(OR(BJ5<launch_month,BJ11<n1_from),0,ROUNDUP(BJ11/r_n1,0)) -> 6
A30: Gerentes de sucesso (CS) | B30: pessoas | C30: =IF(C5<launch_month,0,MAX(1,ROUNDUP(C11/r_cs,0))) -> 0 | D30: =IF(D5<launch_month,0,MAX(1,ROUNDUP(D11/r_cs,0))) -> 0 | E30: =IF(E5<launch_month,0,MAX(1,ROUNDUP(E11/r_cs,0))) -> 0 | F30: =IF(F5<launch_month,0,MAX(1,ROUNDUP(F11/r_cs,0))) -> 1 | G30: =IF(G5<launch_month,0,MAX(1,ROUNDUP(G11/r_cs,0))) -> 1 | H30: =IF(H5<launch_month,0,MAX(1,ROUNDUP(H11/r_cs,0))) -> 1 | I30: =IF(I5<launch_month,0,MAX(1,ROUNDUP(I11/r_cs,0))) -> 1 | J30: =IF(J5<launch_month,0,MAX(1,ROUNDUP(J11/r_cs,0))) -> 1 | ... BJ30: =IF(BJ5<launch_month,0,MAX(1,ROUNDUP(BJ11/r_cs,0))) -> 9
A31: Analistas zootécnicos/veterinários N2 | B31: pessoas | C31: =IF(C5<launch_month,0,ROUNDUP(C13/r_n2,0)) -> 0 | D31: =IF(D5<launch_month,0,ROUNDUP(D13/r_n2,0)) -> 0 | E31: =IF(E5<launch_month,0,ROUNDUP(E13/r_n2,0)) -> 0 | F31: =IF(F5<launch_month,0,ROUNDUP(F13/r_n2,0)) -> 1 | G31: =IF(G5<launch_month,0,ROUNDUP(G13/r_n2,0)) -> 1 | H31: =IF(H5<launch_month,0,ROUNDUP(H13/r_n2,0)) -> 1 | I31: =IF(I5<launch_month,0,ROUNDUP(I13/r_n2,0)) -> 1 | J31: =IF(J5<launch_month,0,ROUNDUP(J13/r_n2,0)) -> 1 | ... BJ31: =IF(BJ5<launch_month,0,ROUNDUP(BJ13/r_n2,0)) -> 5
A32: Especialistas de implantação | B32: pessoas | C32: =IF(C5<launch_month,0,ROUNDUP(C9/r_onb,0)) -> 0 | D32: =IF(D5<launch_month,0,ROUNDUP(D9/r_onb,0)) -> 0 | E32: =IF(E5<launch_month,0,ROUNDUP(E9/r_onb,0)) -> 0 | F32: =IF(F5<launch_month,0,ROUNDUP(F9/r_onb,0)) -> 1 | G32: =IF(G5<launch_month,0,ROUNDUP(G9/r_onb,0)) -> 1 | H32: =IF(H5<launch_month,0,ROUNDUP(H9/r_onb,0)) -> 1 | I32: =IF(I5<launch_month,0,ROUNDUP(I9/r_onb,0)) -> 1 | J32: =IF(J5<launch_month,0,ROUNDUP(J9/r_onb,0)) -> 1 | ... BJ32: =IF(BJ5<launch_month,0,ROUNDUP(BJ9/r_onb,0)) -> 4
A33: Total da equipe de suporte e sucesso | B33: pessoas | C33: =C29+C30+C31+C32 -> 0 | D33: =D29+D30+D31+D32 -> 0 | E33: =E29+E30+E31+E32 -> 0 | F33: =F29+F30+F31+F32 -> 3 | G33: =G29+G30+G31+G32 -> 3 | H33: =H29+H30+H31+H32 -> 3 | I33: =I29+I30+I31+I32 -> 3 | J33: =J29+J30+J31+J32 -> 3 | ... BJ33: =BJ29+BJ30+BJ31+BJ32 -> 24
A34: Custo dos serviços (COGS)
A35: Infraestrutura variável (por fazenda) | B35: R$ | C35: =-C12*infra_var*C7 -> 0 | D35: =-D12*infra_var*D7 -> 0 | E35: =-E12*infra_var*E7 -> 0 | F35: =-F12*infra_var*F7 -> -112.5 | G35: =-G12*infra_var*G7 -> -336.15 | H35: =-H12*infra_var*H7 -> -557.1162 | I35: =-I12*infra_var*I7 -> -775.43081 | J35: =-J12*infra_var*J7 -> -991.12564 | ... BJ35: =-BJ12*infra_var*BJ7 -> -77487.488
A36: Mensageria | B36: R$ | C36: =-C12*msg*C7 -> 0 | D36: =-D12*msg*D7 -> 0 | E36: =-E12*msg*E7 -> 0 | F36: =-F12*msg*F7 -> -45 | G36: =-G12*msg*G7 -> -134.46 | H36: =-H12*msg*H7 -> -222.84648 | I36: =-I12*msg*I7 -> -310.17232 | J36: =-J12*msg*J7 -> -396.45025 | ... BJ36: =-BJ12*msg*BJ7 -> -30994.995
A37: Infraestrutura fixa | B37: R$ | C37: =-infra_fix*C7 -> -4000 | D37: =-infra_fix*D7 -> -4000 | E37: =-infra_fix*E7 -> -4000 | F37: =-infra_fix*F7 -> -4000 | G37: =-infra_fix*G7 -> -4000 | H37: =-infra_fix*H7 -> -4000 | I37: =-infra_fix*I7 -> -4000 | J37: =-infra_fix*J7 -> -4000 | ... BJ37: =-infra_fix*BJ7 -> -4862.025
A38: Equipe de suporte e sucesso (N1, CS, N2, implantação) | B38: R$ | C38: =-(C29*c_n1+C30*c_cs+C31*c_n2+C32*c_onb)*C7 -> 0 | D38: =-(D29*c_n1+D30*c_cs+D31*c_n2+D32*c_onb)*D7 -> 0 | E38: =-(E29*c_n1+E30*c_cs+E31*c_n2+E32*c_onb)*E7 -> 0 | F38: =-(F29*c_n1+F30*c_cs+F31*c_n2+F32*c_onb)*F7 -> -27000 | G38: =-(G29*c_n1+G30*c_cs+G31*c_n2+G32*c_onb)*G7 -> -27000 | H38: =-(H29*c_n1+H30*c_cs+H31*c_n2+H32*c_onb)*H7 -> -27000 | I38: =-(I29*c_n1+I30*c_cs+I31*c_n2+I32*c_onb)*I7 -> -27000 | J38: =-(J29*c_n1+J30*c_cs+J31*c_n2+J32*c_onb)*J7 -> -27000 | ... BJ38: =-(BJ29*c_n1+BJ30*c_cs+BJ31*c_n2+BJ32*c_onb)*BJ7 -> -227299.67
A39: Ferramentas de suporte (helpdesk, CRM, base de conhecimento) | B39: R$ | C39: =-(C33*tool_seat+C12*tool_farm)*C7 -> 0 | D39: =-(D33*tool_seat+D12*tool_farm)*D7 -> 0 | E39: =-(E33*tool_seat+E12*tool_farm)*E7 -> 0 | F39: =-(F33*tool_seat+F12*tool_farm)*F7 -> -768 | G39: =-(G33*tool_seat+G12*tool_farm)*G7 -> -803.784 | H39: =-(H33*tool_seat+H12*tool_farm)*H7 -> -839.13859 | I39: =-(I33*tool_seat+I12*tool_farm)*I7 -> -874.06893 | J39: =-(J33*tool_seat+J12*tool_farm)*J7 -> -908.5801 | ... BJ39: =-(BJ33*tool_seat+BJ12*tool_farm)*BJ7 -> -19691.036
A40: CUSTO DOS SERVIÇOS | B40: R$ | C40: =SUM(C35:C39) -> -4000 | D40: =SUM(D35:D39) -> -4000 | E40: =SUM(E35:E39) -> -4000 | F40: =SUM(F35:F39) -> -31925.5 | G40: =SUM(G35:G39) -> -32274.394 | H40: =SUM(H35:H39) -> -32619.101 | I40: =SUM(I35:I39) -> -32959.672 | J40: =SUM(J35:J39) -> -33296.156 | ... BJ40: =SUM(BJ35:BJ39) -> -360335.21
A41: LUCRO BRUTO | B41: R$ | C41: =C26+C40 -> -4000 | D41: =D26+D40 -> -4000 | E41: =E26+E40 -> -4000 | F41: =F26+F40 -> -23437.3 | G41: =G26+G40 -> -20276.738 | H41: =H26+H40 -> -17154.102 | I41: =I26+I40 -> -14068.939 | J41: =J26+J40 -> -11020.797 | ... BJ41: =BJ26+BJ40 -> 1108786.1
...

Sheet Memória de cálculo
A1: Memória de cálculo (lógica de cada linha do modelo mensal)
A3: Linha | B3: Fórmula / lógica | C3: Premissas usadas
A4: Novas fazendas | B4: Zero antes do lançamento; depois = novas/mês do ano x multiplicador do cenário. | C4: launch_month, new_farms_y, f_new
A5: Fazendas perdidas | B5: Fazendas ativas do mês anterior x churn mensal x multiplicadores. | C5: churn_m, f_churn, s_churn
A6: Fazendas ativas | B6: Anterior + novas - perdidas.
A7: Vacas atendidas | B7: Fazendas ativas x vacas médias por fazenda (média ponderada pelo mix). | C7: mix_*, herd_*
A8: ARPA de assinatura | B8: Média ponderada de MAIOR(mínimo do plano; vacas do plano x preço por vaca), x reajuste IPCA do ano x multiplicadores de preço. | C8: mix, herd, p_*, min_*, reajuste, f_price, s_price
A9: Assinatura | B9: Fazendas ativas médias do mês x ARPA.
A10: Implantação | B10: Novas fazendas x implantação média ponderada x reajuste. | C10: set_*
A11: Módulos premium / Benchmark | B11: Fazendas médias x % de adoção do ano x preço x reajuste. | C11: adopt_*_y, price_mod, price_bench
A12: Licenças de consultor | B12: Acumulado de novas licenças/mês (a partir do mês 13) x preço. | C12: new_cons_y, price_cons
A13: Evento | B13: Receita anual lançada no mês do evento. | C13: event_rev_y, event_month
A14: Patrocínios | B14: Valor anual / 12, a partir do lançamento. | C14: spons_y
A15: Tributos | B15: Receita bruta x alíquota do ano. | C15: tax_y
A16: N1 | B16: ARREDONDAR.PARA.CIMA(fazendas ativas / fazendas por N1). | C16: r_n1
A17: CS | B17: MÁXIMO(1; ARREDONDAR.PARA.CIMA(fazendas / fazendas por CS)). | C17: r_cs
A18: N2 zootécnico | B18: ARREDONDAR.PARA.CIMA(vacas atendidas / vacas por analista). | C18: r_n2
A19: Implantação (equipe) | B19: ARREDONDAR.PARA.CIMA(novas fazendas do mês / novas por especialista). | C19: r_onb
A20: Custo de suporte | B20: (N1 x custo + CS x custo + N2 x custo + implantação x custo) x reajuste. | C20: c_*
A21: Ferramentas | B21: (Pessoas de suporte x licença + fazendas médias x custo por fazenda) x reajuste. | C21: tool_seat, tool_farm
... A28: Capital de giro | B28: Receber = receita líquida x prazo/30; Pagar = (custos + despesas) x prazo/30; variação mensal entra no fluxo. | C28: dso, dpo
A29: Fluxo operacional | B29: EBITDA + variação do capital de giro.
A30: Caixa | B30: Caixa anterior + fluxo operacional + aportes (tranches = aporte x % em 3 meses definidos). | C30: ask, t1..t3
A31: Balanço | B31: Ativo (caixa + a receber) = Passivo (a pagar) + capital integralizado + lucros acumulados. Conferência = 0.
A32: Break-even operacional | B32: Primeiro mês com EBITDA > 0.
A33: Payback | B33: Primeiro mês, após o ponto mínimo, em que o caixa acumulado (antes de aportes) volta a >= 0.
A34: VPL | B34: Fluxos operacionais anuais descontados à TMA; versão com valor residual soma múltiplo x receita líquida do ano 5. | C34: disc, tv_mult
A35: TIR | B35: Taxa interna de retorno dos mesmos fluxos anuais.
A36: CAC | B36: (Equipe de vendas fixa + comissão + aquisição variável + marketing fixo) / novas fazendas do ano.
A37: LTV | B37: Contribuição mensal por fazenda (ARPA - custo variável por fazenda) / churn mensal.
A38: Payback do CAC | B38: CAC / contribuição mensal por fazenda.
A39: Suporte por escala | B39: Aba Suporte: aplica as mesmas razões de capacidade e custos às fazendas informadas. | C39: r_*, c_*
